<?xml version="1.0"?>
<robot name="simple_gripper">
  <link name="palm">
    <visual>
      <geometry>
        <cylinder length="0.04" radius="0.07"/>
      </geometry>
      <origin rpy="0 0 0" xyz="0 0 0.02"/>
    </visual>
    <collision>
      <geometry>
        <cylinder length="0.04" radius="0.07"/>
      </geometry>
      <origin rpy="0 0 0" xyz="0 0 0.02"/>
    </collision>
    <inertial>
      <mass value="0.1"/>
      <inertia ixx="0.001" ixy="0.0" ixz="0.0" iyy="0.001" iyz="0.0" izz="0.001"/>
    </inertial>
  </link>

  <link name="finger1">
    <visual>
      <geometry>
        <box size="0.02 0.02 0.08"/>
      </geometry>
      <origin rpy="0 0 0" xyz="0 0 0.04"/>
    </visual>
    <collision>
      <geometry>
        <box size="0.02 0.02 0.08"/>
      </geometry>
      <origin rpy="0 0 0" xyz="0 0 0.04"/>
    </collision>
    <inertial>
      <mass value="0.1"/>
      <inertia ixx="0.001" ixy="0.0" ixz="0.0" iyy="0.001" iyz="0.0" izz="0.001"/>
    </inertial>
  </link>

  <link name="finger2">
    <visual>
      <geometry>
        <box size="0.02 0.02 0.08"/>
      </geometry>
      <origin rpy="0 0 0" xyz="0 0 0.04"/>
    </visual>
    <collision>
      <geometry>
        <box size="0.02 0.02 0.08"/>
      </geometry>
      <origin rpy="0 0 0" xyz="0 0 0.04"/>
    </collision>
    <inertial>
      <mass value="0.1"/>
      <inertia ixx="0.001" ixy="0.0" ixz="0.0" iyy="0.001" iyz="0.0" izz="0.001"/>
    </inertial>
  </link>

  <!-- make fingers soft and sticky -->

  <gazebo reference="finger1">
    <mu1 value="0.8" />
    <mu2 value="0.8" />
    <kp  value="10000000" />
  </gazebo>

  <gazebo reference="finger2">
    <mu1 value="0.8" />
    <mu2 value="0.8" />
    <kp  value="10000000" />
  </gazebo>

  <!-- one finger is fixed -->

  <joint name="palm_to_finger1" type="fixed">
    <parent link="palm"/>
    <child link="finger1"/>
    <origin xyz="0.05 0 0.04"/>
  </joint>

  <!-- other finger can slide -->

  <joint name="palm_to_finger2" type="prismatic">
    <parent link="palm"/>
    <child link="finger2"/>
    <limit effort="1000.0" lower="0.0" upper="0.065" velocity="0.5"/>
    <origin xyz="-0.05 0 0.04"/>
  </joint>

  <transmission name="finger_trans">
    <type>transmission_interface/SimpleTransmission</type>
    <actuator name="finger_motor">
      <mechanicalReduction>1</mechanicalReduction>
    </actuator>
    <joint name="palm_to_finger2">
      <hardwareInterface>hardware_interface/EffortJointInterface</hardwareInterface>
    </joint>
  </transmission>

</robot>
