<?xml version="1.0"?>
<robot name="simple_gripper">
  <link name="palm">
    <visual>
      <geometry>
        <cylinder length="0.04" radius="0.07"/>
      </geometry>
      <origin rpy="0 0 0" xyz="0 0 0.02"/>
    </visual>
    <collision>
      <geometry>
        <cylinder length="0.04" radius="0.07"/>
      </geometry>
      <origin rpy="0 0 0" xyz="0 0 0.02"/>
    </collision>
    <inertial>
      <mass value="0.1"/>
      <inertia ixx="0.001" ixy="0.0" ixz="0.0" iyy="0.001" iyz="0.0" izz="0.001"/>
    </inertial>
  </link>

  <link name="finger1">
    <visual>
      <geometry>
        <box size="0.02 0.02 0.08"/>
      </geometry>
      <origin rpy="0 0 0" xyz="0 0 0.04"/>
    </visual>
    <collision>
      <geometry>
        <box size="0.02 0.02 0.08"/>
      </geometry>
      <origin rpy="0 0 0" xyz="0 0 0.04"/>
    </collision>
    <inertial>
      <mass value="0.1"/>
      <inertia ixx="0.001" ixy="0.0" ixz="0.0" iyy="0.001" iyz="0.0" izz="0.001"/>
    </inertial>
  </link>

  <link name="finger2">
    <visual>
      <geometry>
        <box size="0.02 0.02 0.08"/>
      </geometry>
      <origin rpy="0 0 0" xyz="0 0 0.04"/>
    </visual>
    <collision>
      <geometry>
        <box size="0.02 0.02 0.08"/>
      </geometry>
      <origin rpy="0 0 0" xyz="0 0 0.04"/>
    </collision>
    <inertial>
      <mass value="0.1"/>
      <inertia ixx="0.001" ixy="0.0" ixz="0.0" iyy="0.001" iyz="0.0" izz="0.001"/>
    </inertial>
  </link>

  <!-- make fingers soft and sticky -->
  <!-- removing - using grasp fix instead 
  <gazebo reference="finger1">
    <mu1 value="0.8" />
    <mu2 value="0.8" />
    <kp  value="10000000" />
  </gazebo>

  <gazebo reference="finger2">
    <mu1 value="0.8" />
    <mu2 value="0.8" />
    <kp  value="10000000" />
  </gazebo>
  -->

  <!-- one finger is fixed -->
  <!--
  <joint name="palm_to_finger1" type="fixed">
    <parent link="palm"/>
    <child link="finger1"/>
    <origin xyz="0.05 0 0.04"/>
  </joint>
  -->

  <!-- fingers can slide -->

  <joint name="palm_to_finger1" type="prismatic">
    <parent link="palm"/>
    <child link="finger1"/>
    <limit effort="1" lower="0.0" upper="0.03" velocity="0.05"/>
    <origin xyz="0.05 0 0.04" rpy="0 0 3.14159265"/>
  </joint>

  <joint name="palm_to_finger2" type="prismatic">
    <parent link="palm"/>
    <child link="finger2"/>
    <limit effort="1.0" lower="0.0" upper="0.03" velocity="0.05"/>
    <origin xyz="-0.05 0 0.04"/>
  </joint>

  <transmission name="finger1_trans">
    <type>transmission_interface/SimpleTransmission</type>
    <actuator name="finger1_motor">
      <mechanicalReduction>1</mechanicalReduction>
    </actuator>
    <joint name="palm_to_finger1">
      <hardwareInterface>hardware_interface/EffortJointInterface</hardwareInterface>
    </joint>
  </transmission>

  <transmission name="finger2_trans">
    <type>transmission_interface/SimpleTransmission</type>
    <actuator name="finger2_motor">
      <mechanicalReduction>1</mechanicalReduction>
    </actuator>
    <joint name="palm_to_finger2">
      <hardwareInterface>hardware_interface/EffortJointInterface</hardwareInterface>
    </joint>
  </transmission>

  <gazebo>
    <plugin name="gazebo_grasp_fix" filename="libgazebo_grasp_fix.so">
        <arm>
           <arm_name>arm</arm_name>
           <palm_link> wrist_3_link  </palm_link>
           <gripper_link> finger1 </gripper_link>
           <gripper_link> finger2 </gripper_link>
        </arm>
       <forces_angle_tolerance>100</forces_angle_tolerance>
       <update_rate>4</update_rate>
       <grip_count_threshold>4</grip_count_threshold>
       <max_grip_count>8</max_grip_count>
       <release_tolerance>0.005</release_tolerance>
       <disable_collisions_on_attach>false</disable_collisions_on_attach>
       <contact_topic>__default_topic__</contact_topic>
    </plugin>
  </gazebo>

</robot>
